<?xml version="1.0" encoding="utf-8"?>
<mujoco model="air_hockey_table">
	<option timestep="0.001" cone="elliptic" impratio="1"></option>
	<asset>
		<material name="grey" specular="0.5" shininess="0.25" rgba="0.8 0.8 0.8 1"></material>
		<material name="white" specular="0.5" shininess="0.25" rgba="1.0 1.0 1.0 1"></material>
		<material name="red" specular="0.5" shininess="0.25" rgba="1.0 0.0 0.0 1"></material>
		<material name="blue" specular="0.5" shininess="0.25" rgba="0.0 0.0 1.0 1"></material>
		<material name="transparent" specular="0.5" shininess="0.25" rgba="0.0 0.0 1.0 0"></material>
		<material name="floorplane" reflectance="0.01" shininess="0.0" specular="0.0" texrepeat="2 2" texture="texplane" texuniform="true"></material>
		<material name="walls_mat" reflectance="0.0" shininess="0.1" specular="0.1" texrepeat="3 3" texture="tex-light-gray-plaster" texuniform="true"></material>
		<material name="table_ceramic" reflectance="0.0" shininess="0.0" specular="0.2" texrepeat="1 1" texture="tex-ceramic"></material>
		<texture type="skybox" builtin="gradient" rgb1="0.3 0.5 0.7" rgb2="0 0 0" width="512" height="3072"></texture>
		<texture file="../textures/light-gray-floor-tile.png" type="2d" name="texplane"></texture>
		<texture file="../textures/light-gray-plaster.png" type="2d" name="tex-light-gray-plaster"></texture>
		<texture file="../textures/ceramic.png" type="cube" name="tex-ceramic"></texture>
	</asset>
	<default>
		<geom condim="4" solref="0.02 0.3"></geom>
		<default class="rim">
			<geom type="box" material="grey" condim="6" friction="10000 0.0 0.0" priority="1" solref="-800000 -250" solimp="0.99 0.999 0.001 0.5 2" group="1"></geom>
		</default>
	</default>
	<worldbody>
		<site name="goal_region" type="cylinder" pos="0.05 0.3 1" size="0.05" rgba="1 0 0 0" axisangle="0 1 0 -0.09"></site>
		<site name="desired_vel" type="cylinder" pos="0.3 0 1" size="0.005 0.05" rgba="0 0 1 0" axisangle="1 1 0 1.480796326794896"></site>
		<site name="puck_vis" type="ellipsoid" size="0.03165 0.03165 0.004" pos="0 0 -0.05"></site>
		<site name="puck_vis_rot" type="cylinder" size="0.0045 0.006" rgba="1 0 0 1" pos="0 0 -0.05"></site>
		<body name="table" pos="0.8 0 1.0" axisangle="0 1 0 -0.09">
			<body name="table_surface">
				<geom name="surface" type="box" material="white" size="1.064 0.609 0.0505" pos="0 0 -0.0505" condim="4" friction="0.08 0.08 0.0" priority="1" group="1" contype="1" conaffinity="1"></geom>
			</body>
			<body name="rim">
				<geom name="rim_home_l" class="rim" size="0.01 0.1945 0.005" pos="-1.019 0.3245 0.005" group="1"></geom>
				<geom name="rim_home_r" class="rim" size="0.045 0.1945 0.005" pos="-1.019 -0.3245 0.005" group="1"></geom>
				<geom name="rim_home_bound_l" class="rim" type="cylinder" size="0.005 0.005" pos="-0.979 0.13 0.005" group="1"></geom>
				<geom name="rim_home_bound_l_tail" class="rim" size="0.0425 0.005 0.005" pos="-1.0215 0.13 0.005"></geom>
				<geom name="rim_home_bound_r" class="rim" type="cylinder" size="0.005 0.005" pos="-0.979 -0.13 0.005" group="1"></geom>
				<geom name="rim_home_bound_r_tail" class="rim" size="0.0425 0.005 0.005" pos="-1.0215 -0.13 0.005" group="1"></geom>
				<geom name="rim_home_top" class="rim" size="0.045 0.519 0.01" pos="-1.019 0 0.02" group="1"></geom>
				<geom name="rim_left" class="rim" size="1.064 0.045 0.015" pos="0 0.564 0.015" group="1"></geom>
				<geom name="rim_right" class="rim" size="1.064 0.045 0.015" pos="0 -0.564 0.015" group="1"></geom>
				<geom name="rim_away_l" class="rim" size="0.01 0.1945 0.005" pos="1.019 0.3245 0.005" group="1"></geom>
				<geom name="rim_away_r" class="rim" size="0.01 0.1945 0.005" pos="1.019 -0.3245 0.005" group="1"></geom>
				<geom name="rim_away_bound_l" class="rim" type="cylinder" size="0.005 0.005" pos="0.979 0.13 0.005" group="1"></geom>
				<geom name="rim_away_bound_l_tail" class="rim" size="0.0425 0.005 0.005" pos="1.0215 0.13 0.005" group="1"></geom>
				<geom name="rim_away_bound_r" class="rim" type="cylinder" size="0.005 0.005" pos="0.979 -0.13 0.005" group="1"></geom>
				<geom name="rim_away_bound_r_tail" class="rim" size="0.0425 0.005 0.005" pos="1.0215 -0.13 0.005" group="1"></geom>
				<geom name="rim_away_top" class="rim" size="0.045 0.519 0.01" pos="1.019 0 0.02" group="1"></geom>
			</body>
		</body>
		<body name="base" pos="0.8 -0.3 1.2" axisangle="0 1 0 -0.09">
			<joint name="puck_x" type="slide" axis="1 0 0" damping="0.08" limited="false"></joint>
			<joint name="puck_y" type="slide" axis="0 1 0" damping="0.08" limited="false"></joint>
			<joint name="puck_yaw" type="hinge" axis="0 0 1" damping="2e-6" limited="false"></joint>
			<body name="puck">
				<geom pos="0 0 -0.2" name="puck" type="cylinder" material="red" size="0.03175 0.009" condim="4" priority="0" group="1"></geom>
				<geom pos="0.02 0 -0.2" type="cylinder" material="blue" size="0.01 0.0091" condim="4" contype="0" conaffinity="0" group="1"></geom>
				<inertial pos="0 0 0" mass="0.01" diaginertia="2.5e-6 2.5e-6 5e-6"></inertial>
			</body>
		</body>
		<camera mode="fixed" name="frontview" pos="1 0 1.45" quat="0.56 0.43 0.43 0.56"></camera>
		<camera mode="fixed" name="birdview" pos="-0.2 0 7.0" quat="0.7071 0 0 0.7071"></camera>
		<camera mode="fixed" name="agentview" pos="0.5 0 3" quat="0.7071 0 0 0.7071"></camera>
		<camera mode="fixed" name="sideview" pos="0.75 1.85 1.6" quat="0.009905065491771751 0.006877963156909582 0.5912228352893879 0.806418094001364"></camera>
		<light pos="0 0 3" dir="0 0 -1" directional="true"></light>
		<geom pos="0 0 -0.1" name="floor" size="0 0 0.05" type="plane" material="floorplane" group="1"></geom>
		<geom pos="-1.25 2.25 1.5" quat="0.6532815 0.6532815 0.2705981 0.2705981" size="1.06 1.5 0.01" type="box" conaffinity="0" contype="0" group="1" name="wall_leftcorner_visual" material="walls_mat"></geom>
		<geom pos="-1.25 -2.25 1.5" quat="0.6532815 0.6532815 -0.2705981 -0.2705981" size="1.06 1.5 0.01" type="box" conaffinity="0" contype="0" group="1" name="wall_rightcorner_visual" material="walls_mat"></geom>
		<geom pos="1.25 3 1.5" quat="0.7071 0.7071 0 0" size="1.75 1.5 0.01" type="box" conaffinity="0" contype="0" group="1" name="wall_left_visual" material="walls_mat"></geom>
		<geom pos="1.25 -3 1.5" quat="0.7071 -0.7071 0 0" size="1.75 1.5 0.01" type="box" conaffinity="0" contype="0" group="1" name="wall_right_visual" material="walls_mat"></geom>
		<geom pos="-2 0 1.5" quat="0.5 0.5 0.5 0.5" size="1.5 1.5 0.01" type="box" conaffinity="0" contype="0" group="1" name="wall_rear_visual" material="walls_mat"></geom>
		<geom pos="3 0 1.5" quat="0.5 0.5 -0.5 -0.5" size="3 1.5 0.01" type="box" conaffinity="0" contype="0" group="1" name="wall_front_visual" material="walls_mat"></geom>
	</worldbody>
	<contact>
		<exclude body1="puck" body2="table_surface"></exclude>
	</contact>
</mujoco>